<?xml version="1.0" ?>
<robot name="Cobot" xmlns:xacro="http://www.ros.org/wiki/xacro">

<xacro:include filename="$(find cobot_description)/urdf/materials.xacro" />
<xacro:include filename="$(find cobot_description)/urdf/cobot.trans" />
<xacro:include filename="$(find cobot_description)/urdf/cobot.gazebo" />
<link name= "world"/>
<link name="base_link">
  <inertial>
    <origin xyz="-1.2972850039755492e-17 0.0 0.03670442150572817" rpy="0 0 0"/>
    <mass value="5.503442487223917"/>
    <inertia ixx="0.007142" iyy="0.007142" izz="0.007951" ixy="-0.0" iyz="-0.0" ixz="-0.0"/>
  </inertial>
  <visual>
    <origin xyz="0 0 0" rpy="0 0 0"/>
    <geometry>
      <mesh filename="package://cobot_description/meshes/base_link.stl" scale="0.001 0.001 0.001"/>
    </geometry>
    <material name="silver"/>
  </visual>
  <collision>
    <origin xyz="0 0 0" rpy="0 0 0"/>
    <geometry>
      <mesh filename="package://cobot_description/meshes/base_link.stl" scale="0.001 0.001 0.001"/>
    </geometry>
  </collision>
</link>

<link name="base_joint_1">
  <inertial>
    <origin xyz="-5.95929710844456e-10 5.996805720800185e-09 0.06166062192697862" rpy="0 0 0"/>
    <mass value="10.611591187770788"/>
    <inertia ixx="0.014633" iyy="0.028949" izz="0.0282" ixy="0.0" iyz="0.0" ixz="-0.0"/>
  </inertial>
  <visual>
    <origin xyz="-0.0 -0.0 -0.08" rpy="0 0 0"/>
    <geometry>
      <mesh filename="package://cobot_description/meshes/base_joint_1.stl" scale="0.001 0.001 0.001"/>
    </geometry>
    <material name="silver"/>
  </visual>
  <collision>
    <origin xyz="-0.0 -0.0 -0.08" rpy="0 0 0"/>
    <geometry>
      <mesh filename="package://cobot_description/meshes/base_joint_1.stl" scale="0.001 0.001 0.001"/>
    </geometry>
  </collision>
</link>

<link name="Shoulder_1">
  <inertial>
    <origin xyz="-0.08000000000000002 -6.6011772650993885e-18 0.1193073921952982" rpy="0 0 0"/>
    <mass value="10.815545655264254"/>
    <inertia ixx="0.103047" iyy="0.199811" izz="0.112944" ixy="0.0" iyz="-0.0" ixz="-0.0"/>
  </inertial>
  <visual>
    <origin xyz="-0.08 -0.0 -0.15" rpy="0 0 0"/>
    <geometry>
      <mesh filename="package://cobot_description/meshes/Shoulder_1.stl" scale="0.001 0.001 0.001"/>
    </geometry>
    <material name="silver"/>
  </visual>
  <collision>
    <origin xyz="-0.08 -0.0 -0.15" rpy="0 0 0"/>
    <geometry>
      <mesh filename="package://cobot_description/meshes/Shoulder_1.stl" scale="0.001 0.001 0.001"/>
    </geometry>
  </collision>
</link>

<link name="elbow_joint_1">
  <inertial>
    <origin xyz="-0.08997963492715857 -0.11061140786869318 -0.004921535193373183" rpy="0 0 0"/>
    <mass value="26.774299686619884"/>
    <inertia ixx="0.30536" iyy="0.051149" izz="0.321794" ixy="8e-06" iyz="3.2e-05" ixz="-0.0"/>
  </inertial>
  <visual>
    <origin xyz="-0.09 -0.0 -0.4" rpy="0 0 0"/>
    <geometry>
      <mesh filename="package://cobot_description/meshes/elbow_joint_1.stl" scale="0.001 0.001 0.001"/>
    </geometry>
    <material name="silver"/>
  </visual>
  <collision>
    <origin xyz="-0.09 -0.0 -0.4" rpy="0 0 0"/>
    <geometry>
      <mesh filename="package://cobot_description/meshes/elbow_joint_1.stl" scale="0.001 0.001 0.001"/>
    </geometry>
  </collision>
</link>

<link name="wrist1_1">
  <inertial>
    <origin xyz="0.055000000000000014 0.0 -0.07187789128386346" rpy="0 0 0"/>
    <mass value="6.5613388718047485"/>
    <inertia ixx="0.029992" iyy="0.057258" izz="0.035263" ixy="-0.0" iyz="0.0" ixz="0.0"/>
  </inertial>
  <visual>
    <origin xyz="0.055 0.25 -0.4" rpy="0 0 0"/>
    <geometry>
      <mesh filename="package://cobot_description/meshes/wrist1_1.stl" scale="0.001 0.001 0.001"/>
    </geometry>
    <material name="silver"/>
  </visual>
  <collision>
    <origin xyz="0.055 0.25 -0.4" rpy="0 0 0"/>
    <geometry>
      <mesh filename="package://cobot_description/meshes/wrist1_1.stl" scale="0.001 0.001 0.001"/>
    </geometry>
  </collision>
</link>

<link name="wrist2_1">
  <inertial>
    <origin xyz="-0.0600072785371625 -0.010924894509253713 -0.004877997934775419" rpy="0 0 0"/>
    <mass value="5.063124340718995"/>
    <inertia ixx="0.005913" iyy="0.005825" izz="0.007459" ixy="-1e-06" iyz="1.8e-05" ixz="0.0"/>
  </inertial>
  <visual>
    <origin xyz="-0.06 0.25 -0.25" rpy="0 0 0"/>
    <geometry>
      <mesh filename="package://cobot_description/meshes/wrist2_1.stl" scale="0.001 0.001 0.001"/>
    </geometry>
    <material name="silver"/>
  </visual>
  <collision>
    <origin xyz="-0.06 0.25 -0.25" rpy="0 0 0"/>
    <geometry>
      <mesh filename="package://cobot_description/meshes/wrist2_1.stl" scale="0.001 0.001 0.001"/>
    </geometry>
  </collision>
</link>

<joint name="fixed" type="fixed"> 
  <parent link="world"/> 
  <child link="base_link"/>
</joint>


<joint name="BJ" type="continuous">
  <origin xyz="0.0 0.0 0.08" rpy="0 0 0"/>
  <parent link="base_link"/>
  <child link="base_joint_1"/>
  <axis xyz="0.0 0.0 1.0"/>
</joint>

<joint name="SJ" type="continuous">
  <origin xyz="0.08 0.0 0.07" rpy="0 0 0"/>
  <parent link="base_joint_1"/>
  <child link="Shoulder_1"/>
  <axis xyz="1.0 0.0 0.0"/>
</joint>

<joint name="EJ" type="continuous">
  <origin xyz="0.01 0.0 0.25" rpy="0 0 0"/>
  <parent link="Shoulder_1"/>
  <child link="elbow_joint_1"/>
  <axis xyz="1.0 0.0 0.0"/>
</joint>

<joint name="W1J" type="continuous">
  <origin xyz="-0.145 -0.25 0.0" rpy="0 0 0"/>
  <parent link="elbow_joint_1"/>
  <child link="wrist1_1"/>
  <axis xyz="1.0 0.0 0.0"/>
</joint>

<joint name="W2J" type="continuous">
  <origin xyz="0.115 0.0 -0.15" rpy="0 0 0"/>
  <parent link="wrist1_1"/>
  <child link="wrist2_1"/>
  <axis xyz="1.0 0.0 0.0"/>
</joint>

</robot>
